Workbook

Sheet Dashboard
B1: CUCM Greenfield Deployment Workbook
B2: Fill the sheets left to right, then run the CUCM Greenfield Deployer (deployer_app.py). Status columns are written back by the tool.
B4: Cluster
B5: CUCM Publisher
B6: AXL User
B7: AXL Version | C7: Auto
B8: Password is asked by the tool - never stored in this file.
B10: Sheet (deploy order) | C10: Configures | D10: Rows | E10: Success | F10: Failed | G10: Exists | H10: Pending | I10: Notes
B11: Date Time Groups | C11: DateTimeGroup | D11: =COUNTA('Date Time Groups'!B3:B5003) | E11: =COUNTIF('Date Time Groups'!G3:G5003,"Success")+COUNTIF('Date Time Groups'!G3:G5003,"Updated")+COUNTIF('Date Time Groups'!G3:G5003,"Deleted") | F11: =COUNTIF('Date Time Groups'!G3:G5003,"Failed") | G11: =COUNTIF('Date Time Groups'!G3:G5003,"Exists") | H11: =D11-E11-F11-G11 | I11: Date/Time Groups used by Device Pools.
B12: Regions | C12: Region | D12: =COUNTA('Regions'!B3:B5003) | E12: =COUNTIF('Regions'!C3:C5003,"Success")+COUNTIF('Regions'!C3:C5003,"Updated")+COUNTIF('Regions'!C3:C5003,"Deleted") | F12: =COUNTIF('Regions'!C3:C5003,"Failed") | G12: =COUNTIF('Regions'!C3:C5003,"Exists") | H12: =D12-E12-F12-G12 | I12: Regions. Codec / bandwidth between regions goes on the 'Region Relations' sheet.
B13: Region Relations | C13: Region | D13: =COUNTA('Region Relations'!B3:B5003) | E13: =COUNTIF('Region Relations'!I3:I5003,"Success")+COUNTIF('Region Relations'!I3:I5003,"Updated")+COUNTIF('Region Relations'!I3:I5003,"Deleted") | F13: =COUNTIF('Region Relations'!I3:I5003,"Failed") | G13: =COUNTIF('Region Relations'!I3:I5003,"Exists") | H13: =D13-E13-F13-G13 | I13: One row per region pair. Applied with updateRegion after the regions exist.
B14: Locations | C14: Location | D14: =COUNTA('Locations'!B3:B5003) | E14: =COUNTIF('Locations'!K3:K5003,"Success")+COUNTIF('Locations'!K3:K5003,"Updated")+COUNTIF('Locations'!K3:K5003,"Deleted") | F14: =COUNTIF('Locations'!K3:K5003,"Failed") | G14: =COUNTIF('Locations'!K3:K5003,"Exists") | H14: =D14-E14-F14-G14 | I14: Enhanced Locations CAC. Each location is linked to one other (normally Hub_None).
B15: CallManager Groups | C15: CallManagerGroup | D15: =COUNTA('CallManager Groups'!B3:B5003) | E15: =COUNTIF('CallManager Groups'!E3:E5003,"Success")+COUNTIF('CallManager Groups'!E3:E5003,"Updated")+COUNTIF('CallManager Groups'!E3:E5003,"Deleted") | F15: =COUNTIF('CallManager Groups'!E3:E5003,"Failed") | G15: =COUNTIF('CallManager Groups'!E3:E5003,"Exists") | H15: =D15-E15-F15-G15
B16: Partitions | C16: RoutePartition | D16: =COUNTA('Partitions'!B3:B5003) | E16: =COUNTIF('Partitions'!G3:G5003,"Success")+COUNTIF('Partitions'!G3:G5003,"Updated")+COUNTIF('Partitions'!G3:G5003,"Deleted") | F16: =COUNTIF('Partitions'!G3:G5003,"Failed") | G16: =COUNTIF('Partitions'!G3:G5003,"Exists") | H16: =D16-E16-F16-G16
B17: Calling Search Spaces | C17: Css | D17: =COUNTA('Calling Search Spaces'!B3:B5003) | E17: =COUNTIF('Calling Search Spaces'!E3:E5003,"Success")+COUNTIF('Calling Search Spaces'!E3:E5003,"Updated")+COUNTIF('Calling Search Spaces'!E3:E5003,"Deleted") | F17: =COUNTIF('Calling Search Spaces'!E3:E5003,"Failed") | G17: =COUNTIF('Calling Search Spaces'!E3:E5003,"Exists") | H17: =D17-E17-F17-G17
B18: Media Resource Groups | C18: MediaResourceGroup | D18: =COUNTA('Media Resource Groups'!B3:B5003) | E18: =COUNTIF('Media Resource Groups'!F3:F5003,"Success")+COUNTIF('Media Resource Groups'!F3:F5003,"Updated")+COUNTIF('Media Resource Groups'!F3:F5003,"Deleted") | F18: =COUNTIF('Media Resource Groups'!F3:F5003,"Failed") | G18: =COUNTIF('Media Resource Groups'!F3:F5003,"Exists") | H18: =D18-E18-F18-G18
B19: Media Resource Lists | C19: MediaResourceList | D19: =COUNTA('Media Resource Lists'!B3:B5003) | E19: =COUNTIF('Media Resource Lists'!D3:D5003,"Success")+COUNTIF('Media Resource Lists'!D3:D5003,"Updated")+COUNTIF('Media Resource Lists'!D3:D5003,"Deleted") | F19: =COUNTIF('Media Resource Lists'!D3:D5003,"Failed") | G19: =COUNTIF('Media Resource Lists'!D3:D5003,"Exists") | H19: =D19-E19-F19-G19
B20: SRST References | C20: Srst | D20: =COUNTA('SRST References'!B3:B5003) | E20: =COUNTIF('SRST References'!G3:G5003,"Success")+COUNTIF('SRST References'!G3:G5003,"Updated")+COUNTIF('SRST References'!G3:G5003,"Deleted") | F20: =COUNTIF('SRST References'!G3:G5003,"Failed") | G20: =COUNTIF('SRST References'!G3:G5003,"Exists") | H20: =D20-E20-F20-G20
B21: Device Pools | C21: DevicePool | D21: =COUNTA('Device Pools'!B3:B5003) | E21: =COUNTIF('Device Pools'!P3:P5003,"Success")+COUNTIF('Device Pools'!P3:P5003,"Updated")+COUNTIF('Device Pools'!P3:P5003,"Deleted") | F21: =COUNTIF('Device Pools'!P3:P5003,"Failed") | G21: =COUNTIF('Device Pools'!P3:P5003,"Exists") | H21: =D21-E21-F21-G21
B22: SIP Trunks | C22: SipTrunk | D22: =COUNTA('SIP Trunks'!B3:B5003) | E22: =COUNTIF('SIP Trunks'!S3:S5003,"Success")+COUNTIF('SIP Trunks'!S3:S5003,"Updated")+COUNTIF('SIP Trunks'!S3:S5003,"Deleted") | F22: =COUNTIF('SIP Trunks'!S3:S5003,"Failed") | G22: =COUNTIF('SIP Trunks'!S3:S5003,"Exists") | H22: =D22-E22-F22-G22
B23: MGCP Gateways | C23: Gateway | D23: =COUNTA('MGCP Gateways'!B3:B5003) | E23: =COUNTIF('MGCP Gateways'!H3:H5003,"Success")+COUNTIF('MGCP Gateways'!H3:H5003,"Updated")+COUNTIF('MGCP Gateways'!H3:H5003,"Deleted") | F23: =COUNTIF('MGCP Gateways'!H3:H5003,"Failed") | G23: =COUNTIF('MGCP Gateways'!H3:H5003,"Exists") | H23: =D23-E23-F23-G23 | I23: MGCP gateway + modules. PRI endpoints are configured afterwards in CCMAdmin.
B24: Route Groups | C24: RouteGroup | D24: =COUNTA('Route Groups'!B3:B5003) | E24: =COUNTIF('Route Groups'!E3:E5003,"Success")+COUNTIF('Route Groups'!E3:E5003,"Updated")+COUNTIF('Route Groups'!E3:E5003,"Deleted") | F24: =COUNTIF('Route Groups'!E3:E5003,"Failed") | G24: =COUNTIF('Route Groups'!E3:E5003,"Exists") | H24: =D24-E24-F24-G24
B25: Route Lists | C25: RouteList | D25: =COUNTA('Route Lists'!B3:B5003) | E25: =COUNTIF('Route Lists'!H3:H5003,"Success")+COUNTIF('Route Lists'!H3:H5003,"Updated")+COUNTIF('Route Lists'!H3:H5003,"Deleted") | F25: =COUNTIF('Route Lists'!H3:H5003,"Failed") | G25: =COUNTIF('Route Lists'!H3:H5003,"Exists") | H25: =D25-E25-F25-G25
B26: Route Patterns | C26: RoutePattern | D26: =COUNTA('Route Patterns'!B3:B5003) | E26: =COUNTIF('Route Patterns'!Q3:Q5003,"Success")+COUNTIF('Route Patterns'!Q3:Q5003,"Updated")+COUNTIF('Route Patterns'!Q3:Q5003,"Deleted") | F26: =COUNTIF('Route Patterns'!Q3:Q5003,"Failed") | G26: =COUNTIF('Route Patterns'!Q3:Q5003,"Exists") | H26: =D26-E26-F26-G26
B27: Translation Patterns | C27: TransPattern | D27: =COUNTA('Translation Patterns'!B3:B5003) | E27: =COUNTIF('Translation Patterns'!P3:P5003,"Success")+COUNTIF('Translation Patterns'!P3:P5003,"Updated")+COUNTIF('Translation Patterns'!P3:P5003,"Deleted") | F27: =COUNTIF('Translation Patterns'!P3:P5003,"Failed") | G27: =COUNTIF('Translation Patterns'!P3:P5003,"Exists") | H27: =D27-E27-F27-G27
B28: Calling Party Xforms | C28: CallingPartyTransformationPattern | D28: =COUNTA('Calling Party Xforms'!B3:B5003) | E28: =COUNTIF('Calling Party Xforms'!J3:J5003,"Success")+COUNTIF('Calling Party Xforms'!J3:J5003,"Updated")+COUNTIF('Calling Party Xforms'!J3:J5003,"Deleted") | F28: =COUNTIF('Calling Party Xforms'!J3:J5003,"Failed") | G28: =COUNTIF('Calling Party Xforms'!J3:J5003,"Exists") | H28: =D28-E28-F28-G28 | I28: Calling Party Transformation Patterns.
B29: Called Party Xforms | C29: CalledPartyTransformationPattern | D29: =COUNTA('Called Party Xforms'!B3:B5003) | E29: =COUNTIF('Called Party Xforms'!H3:H5003,"Success")+COUNTIF('Called Party Xforms'!H3:H5003,"Updated")+COUNTIF('Called Party Xforms'!H3:H5003,"Deleted") | F29: =COUNTIF('Called Party Xforms'!H3:H5003,"Failed") | G29: =COUNTIF('Called Party Xforms'!H3:H5003,"Exists") | H29: =D29-E29-F29-G29 | I29: Called Party Transformation Patterns.
B30: Voicemail Pilots | C30: VoiceMailPilot | D30: =COUNTA('Voicemail Pilots'!B3:B5003) | E30: =COUNTIF('Voicemail Pilots'!F3:F5003,"Success")+COUNTIF('Voicemail Pilots'!F3:F5003,"Updated")+COUNTIF('Voicemail Pilots'!F3:F5003,"Deleted") | F30: =COUNTIF('Voicemail Pilots'!F3:F5003,"Failed") | G30: =COUNTIF('Voicemail Pilots'!F3:F5003,"Exists") | H30: =D30-E30-F30-G30
B31: Voicemail Profiles | C31: VoiceMailProfile | D31: =COUNTA('Voicemail Profiles'!B3:B5003) | E31: =COUNTIF('Voicemail Profiles'!H3:H5003,"Success")+COUNTIF('Voicemail Profiles'!H3:H5003,"Updated")+COUNTIF('Voicemail Profiles'!H3:H5003,"Deleted") | F31: =COUNTIF('Voicemail Profiles'!H3:H5003,"Failed") | G31: =COUNTIF('Voicemail Profiles'!H3:H5003,"Exists") | H31: =D31-E31-F31-G31
B32: Call Pickup Groups | C32: CallPickupGroup | D32: =COUNTA('Call Pickup Groups'!B3:B5003) | E32: =COUNTIF('Call Pickup Groups'!H3:H5003,"Success")+COUNTIF('Call Pickup Groups'!H3:H5003,"Updated")+COUNTIF('Call Pickup Groups'!H3:H5003,"Deleted") | F32: =COUNTIF('Call Pickup Groups'!H3:H5003,"Failed") | G32: =COUNTIF('Call Pickup Groups'!H3:H5003,"Exists") | H32: =D32-E32-F32-G32
B33: Conference Now | C33: ConferenceNow | D33: =COUNTA('Conference Now'!B3:B5003) | E33: =COUNTIF('Conference Now'!F3:F5003,"Success")+COUNTIF('Conference Now'!F3:F5003,"Updated")+COUNTIF('Conference Now'!F3:F5003,"Deleted") | F33: =COUNTIF('Conference Now'!F3:F5003,"Failed") | G33: =COUNTIF('Conference Now'!F3:F5003,"Exists") | H33: =D33-E33-F33-G33 | I33: Conference Now (CUCM 11.0 and later).
B34: Universal Line Templates | C34: UniversalLineTemplate | D34: =COUNTA('Universal Line Templates'!B3:B5003) | E34: =COUNTIF('Universal Line Templates'!N3:N5003,"Success")+COUNTIF('Universal Line Templates'!N3:N5003,"Updated")+COUNTIF('Universal Line Templates'!N3:N5003,"Deleted") | F34: =COUNTIF('Universal Line Templates'!N3:N5003,"Failed") | G34: =COUNTIF('Universal Line Templates'!N3:N5003,"Exists") | H34: =D34-E34-F34-G34 | I34: Universal Line Templates for self-provisioning / LDAP sync (CUCM 10.0+).
B35: Universal Device Templates | C35: UniversalDeviceTemplate | D35: =COUNTA('Universal Device Templates'!B3:B5003) | E35: =COUNTIF('Universal Device Templates'!Q3:Q5003,"Success")+COUNTIF('Universal Device Templates'!Q3:Q5003,"Updated")+COUNTIF('Universal Device Templates'!Q3:Q5003,"Deleted") | F35: =COUNTIF('Universal Device Templates'!Q3:Q5003,"Failed") | G35: =COUNTIF('Universal Device Templates'!Q3:Q5003,"Exists") | H35: =D35-E35-F35-G35 | I35: Universal Device Templates (CUCM 10.0+).
B36: Directory Numbers | C36: Line | D36: =COUNTA('Directory Numbers'!B3:B5003) | E36: =COUNTIF('Directory Numbers'!Q3:Q5003,"Success")+COUNTIF('Directory Numbers'!Q3:Q5003,"Updated")+COUNTIF('Directory Numbers'!Q3:Q5003,"Deleted") | F36: =COUNTIF('Directory Numbers'!Q3:Q5003,"Failed") | G36: =COUNTIF('Directory Numbers'!Q3:Q5003,"Exists") | H36: =D36-E36-F36-G36
B37: End Users | C37: User | D37: =COUNTA('End Users'!B3:B5003) | E37: =COUNTIF('End Users'!S3:S5003,"Success")+COUNTIF('End Users'!S3:S5003,"Updated")+COUNTIF('End Users'!S3:S5003,"Deleted") | F37: =COUNTIF('End Users'!S3:S5003,"Failed") | G37: =COUNTIF('End Users'!S3:S5003,"Exists") | H37: =D37-E37-F37-G37 | I37: Local end users (LDAP-synced users cannot be added here). Devices and primary extension are applied after the Phones sheet.
B38: Phones | C38: Phone | D38: =COUNTA('Phones'!B3:B5003) | E38: =COUNTIF('Phones'!W3:W5003,"Success")+COUNTIF('Phones'!W3:W5003,"Updated")+COUNTIF('Phones'!W3:W5003,"Deleted") | F38: =COUNTIF('Phones'!W3:W5003,"Failed") | G38: =COUNTIF('Phones'!W3:W5003,"Exists") | H38: =D38-E38-F38-G38
B39: Line Groups | C39: LineGroup | D39: =COUNTA('Line Groups'!B3:B5003) | E39: =COUNTIF('Line Groups'!J3:J5003,"Success")+COUNTIF('Line Groups'!J3:J5003,"Updated")+COUNTIF('Line Groups'!J3:J5003,"Deleted") | F39: =COUNTIF('Line Groups'!J3:J5003,"Failed") | G39: =COUNTIF('Line Groups'!J3:J5003,"Exists") | H39: =D39-E39-F39-G39
B40: Hunt Lists | C40: HuntList | D40: =COUNTA('Hunt Lists'!B3:B5003) | E40: =COUNTIF('Hunt Lists'!H3:H5003,"Success")+COUNTIF('Hunt Lists'!H3:H5003,"Updated")+COUNTIF('Hunt Lists'!H3:H5003,"Deleted") | F40: =COUNTIF('Hunt Lists'!H3:H5003,"Failed") | G40: =COUNTIF('Hunt Lists'!H3:H5003,"Exists") | H40: =D40-E40-F40-G40
B41: Hunt Pilots | C41: HuntPilot | D41: =COUNTA('Hunt Pilots'!B3:B5003) | E41: =COUNTIF('Hunt Pilots'!O3:O5003,"Success")+COUNTIF('Hunt Pilots'!O3:O5003,"Updated")+COUNTIF('Hunt Pilots'!O3:O5003,"Deleted") | F41: =COUNTIF('Hunt Pilots'!O3:O5003,"Failed") | G41: =COUNTIF('Hunt Pilots'!O3:O5003,"Exists") | H41: =D41-E41-F41-G41
B42: Total | D42: =SUM(D11:D41) | E42: =SUM(E11:E41) | F42: =SUM(F11:F41) | G42: =SUM(G11:G41) | H42: =SUM(H11:H41)
...

Sheet Lists
A1: Action | B1: DateTimeGroup.timeZone | C1: DateTimeGroup.Separator | D1: DateTimeGroup.Date Format | E1: DateTimeGroup.Time Format | F1: Region.lossyNetwork | G1: Yes/No | H1: RoutePartition.timeZone | I1: DevicePool.networkLocale | J1: SipTrunk.dtmfSignalingMethod | K1: RouteGroup.distributionAlgorithm | L1: RoutePattern.useCallingPartyPhoneMask | M1: RoutePattern.networkLocation | N1: TransPattern.useCallingPartyPhoneMask | O1: CallingPartyTransformationPattern.useCallingPartyPhoneMask | P1: CallingPartyTransformationPattern.callingLinePresentationBit | Q1: CallPickupGroup.pickupNotification | R1: Line.autoAnswer | S1: Phone.Protocol | T1: Phone.builtInBridgeStatus | U1: LineGroup.distributionAlgorithm | V1: LineGroup.huntAlgorithmNoAnswer | W1: LineGroup.huntAlgorithmBusy | X1: LineGroup.huntAlgorithmNotAvailable
A2: Add | B2: Africa/Abidjan | C2: - | D2: M-D-Y | E2: 12-hour | F2: Keep Current Setting | G2: Yes | H2: Africa/Abidjan | I2: Argentina | J2: No Preference | K2: Top Down | L2: Off | M2: OnNet | N2: Off | O2: Off | P2: Default | Q2: No Alert | R2: Auto Answer Off | S2: SIP | T2: Off | U2: Top Down | V2: Try next member; then, try next group in Hunt List | W2: Try next member; then, try next group in Hunt List | X2: Try next member; then, try next group in Hunt List
A3: Update | B3: Africa/Accra | C3: / | D3: D-M-Y | E3: 24-hour | F3: Use System Default | G3: No | H3: Africa/Accra | I3: Australia | J3: Out of Band | K3: Circular | L3: On | M3: OffNet | N3: On | O3: On | P3: Allowed | Q3: Audio Alert | R3: Auto Answer with Headset | S3: SCCP | T3: On | U3: Circular | V3: Try next member, but do not go to next group | W3: Try next member, but do not go to next group | X3: Try next member, but do not go to next group
A4: Add/Update | B4: Africa/Addis_Ababa | C4: . | D4: Y-M-D | F4: Low Loss | H4: Africa/Addis_Ababa | I4: Austria | J4: RFC 2833 | K4: Longest Idle Time | L4: Default | M4: Use System Default | N4: Default | O4: Default | P4: Restricted | Q4: Visual Alert | R4: Auto Answer with Speakerphone | T4: Default | U4: Longest Idle Time | V4: Skip remaining members, and go directly to next group | W4: Skip remaining members, and go directly to next group | X4: Skip remaining members, and go directly to next group
A5: Delete | B5: Africa/Algiers | D5: M-D-YA | F5: Lossy | H5: Africa/Algiers | I5: Belgium | J5: OOB and RFC 2833 | K5: Broadcast | Q5: Audio and Visual Alert | U5: Broadcast | V5: Stop hunting | W5: Stop hunting | X5: Stop hunting
A6: Skip | B6: Africa/Asmara | D6: D-M-YA | H6: Africa/Asmara | I6: Brazil
B7: Africa/Bamako | D7: YA-M-D | H7: Africa/Bamako | I7: Canada
B8: Africa/Bangui | H8: Africa/Bangui | I8: China
B9: Africa/Banjul | H9: Africa/Banjul | I9: Colombia
B10: Africa/Bissau | H10: Africa/Bissau | I10: Cyprus
B11: Africa/Blantyre | H11: Africa/Blantyre | I11: Czech Republic
B12: Africa/Brazzaville | H12: Africa/Brazzaville | I12: Denmark
B13: Africa/Bujumbura | H13: Africa/Bujumbura | I13: Egypt
B14: Africa/Cairo | H14: Africa/Cairo | I14: Finland
B15: Africa/Casablanca | H15: Africa/Casablanca | I15: France
B16: Africa/Ceuta | H16: Africa/Ceuta | I16: Germany
B17: Africa/Conakry | H17: Africa/Conakry | I17: Ghana
B18: Africa/Dakar | H18: Africa/Dakar | I18: Greece
B19: Africa/Dar_es_Salaam | H19: Africa/Dar_es_Salaam | I19: Hong Kong
... B86: America/Caracas | H86: America/Caracas | I86: Ukraine
B87: America/Cayenne | H87: America/Cayenne
B88: America/Cayman | H88: America/Cayman
B89: America/Chicago | H89: America/Chicago
B90: America/Chihuahua | H90: America/Chihuahua
B91: America/Costa_Rica | H91: America/Costa_Rica
B92: America/Creston | H92: America/Creston
B93: America/Cuiaba | H93: America/Cuiaba
B94: America/Curacao | H94: America/Curacao
B95: America/Danmarkshavn | H95: America/Danmarkshavn
B96: America/Dawson | H96: America/Dawson
B97: America/Dawson_Creek | H97: America/Dawson_Creek
B98: America/Denver | H98: America/Denver
... B471: WET | H471: WET

Sheet Date Time Groups
A1: Action | B1: Name * | C1: Time Zone * | D1: Separator | E1: Date Format | F1: Time Format | G1: Status | H1: Message | I1: Updated
A2: Add / Update / Add/Update / Delete / Skip | B2: e.g. DTG_Muscat | C2: e.g. Asia/Muscat | D2: default: - | E2: default: D-M-Y | F2: default: 12-hour | G2: written by the tool

Sheet Regions
A1: Action | B1: Name * | C1: Status | D1: Message | E1: Updated
A2: Add / Update / Add/Update / Delete / Skip | B2: e.g. RG_HQ | C2: written by the tool

Sheet Region Relations
A1: Action | B1: Region * | C1: Related Region * | D1: Audio Bandwidth | E1: Video Bandwidth kbps | F1: Immersive Video kbps | G1: Lossy Network | H1: Codec Preference List | I1: Status | J1: Message | K1: Updated
A2: Add / Update / Add/Update / Delete / Skip | B2: Region being configured | C2: Same or other region | D2: e.g. 64 kbps / 32 kbps / 8 kbps / Use System Default | default: 64 kbps | E2: default: 384 | F2: default: 2000000000 | G2: default: Use System Default | H2: Use System Default / Factory Default low loss / Factory Default lossy | default: Use System Default | I2: written by the tool

Sheet Locations
A1: Action | B1: Name * | C1: Within Audio kbps | D1: Within Video kbps | E1: Within Immersive kbps | F1: Link To Location | G1: Link Weight | H1: Link Audio kbps | I1: Link Video kbps | J1: Link Immersive kbps | K1: Status | L1: Message | M1: Updated
A2: Add / Update / Add/Update / Delete / Skip | B2: e.g. LOC_HQ | C2: 0 = Unlimited | default: 0 | D2: 0 = Unlimited | default: 0 | E2: 0 = Unlimited | default: 0 | F2: default: Hub_None | G2: default: 50 | H2: default: 0 | I2: default: 0 | J2: default: 0 | K2: written by the tool

Sheet CallManager Groups
A1: Action | B1: Name * | C1: Members (in order) * | D1: TFTP Default | E1: Status | F1: Message | G1: Updated
A2: Add / Update / Add/Update / Delete / Skip | B2: e.g. CMG_SUB1_SUB2 | C2: CallManager names, ; separated, e.g. CM_SUB1;CM_SUB2 | D2: default: No | Yes/No | E2: written by the tool

Sheet Partitions
A1: Action | B1: Name * | C1: Description | D1: Time Schedule | E1: Use Originating Device Time Zone | F1: Time Zone | G1: Status | H1: Message | I1: Updated
A2: Add / Update / Add/Update / Delete / Skip | B2: e.g. PT_Internal | D2: optional | E2: Yes/No | G2: written by the tool

Sheet Calling Search Spaces
A1: Action | B1: Name * | C1: Description | D1: Partitions (in order) | E1: Status | F1: Message | G1: Updated
A2: Add / Update / Add/Update / Delete / Skip | B2: e.g. CSS_Internal | D2: ; separated, top = first searched | E2: written by the tool

Sheet Media Resource Groups
A1: Action | B1: Name * | C1: Description | D1: Use Multicast for MOH | E1: Media Resources * | F1: Status | G1: Message | H1: Updated
A2: Add / Update / Add/Update / Delete / Skip | B2: e.g. MRG_HQ | D2: default: No | Yes/No | E2: Device names ; separated, e.g. ANN_2;CFB_2;MOH_2;MTP_2 | F2: written by the tool

Sheet Media Resource Lists
A1: Action | B1: Name * | C1: Media Resource Groups (in order) * | D1: Status | E1: Message | F1: Updated
A2: Add / Update / Add/Update / Delete / Skip | B2: e.g. MRGL_HQ | D2: written by the tool

Sheet SRST References
A1: Action | B1: Name * | C1: IP Address * | D1: Port | E1: SIP Network/IP | F1: SIP Port | G1: Status | H1: Message | I1: Updated
A2: Add / Update / Add/Update / Delete / Skip | B2: e.g. SRST_HQ | D2: default: 2000 | F2: default: 5060 | G2: written by the tool

Sheet Device Pools
A1: Action | B1: Name * | C1: CallManager Group * | D1: Date Time Group * | E1: Region * | F1: Media Resource List | G1: Location | H1: SRST Reference | I1: Network Locale | J1: Local Route Group | K1: AAR CSS | L1: Device Mobility CSS | M1: Physical Location | N1: Device Mobility Group | O1: Calling Party Transformation CSS | P1: Status | Q1: Message | R1: Updated
A2: Add / Update / Add/Update / Delete / Skip | B2: e.g. DP_HQ | C2: default: Default | H2: Disable / Use Default Gateway / SRST name | default: Disable | J2: Route Group used as 'Standard Local Route Group' | P2: written by the tool

Sheet SIP Trunks
A1: Action | B1: Name * | C1: Description | D1: Device Pool * | E1: Location * | F1: Media Resource List | G1: Inbound CSS | H1: Rerouting CSS | I1: Refer CSS | J1: Security Profile * | K1: SIP Profile * | L1: Destinations * | M1: Run On All Active Nodes | N1: Media Termination Point Required | O1: DTMF Signaling | P1: Presence Group | Q1: Normalization Script | R1: Unknown Prefix | S1: Status | T1: Message | U1: Updated
A2: Add / Update / Add/Update / Delete / Skip | B2: e.g. SIPT_CUBE_HQ | E2: default: Hub_None | J2: default: Non Secure SIP Trunk Profile | K2: default: Standard SIP Profile | L2: ip:port ; separated, e.g. 10.10.1.1:5060;10.10.1.2:5060 | M2: default: Yes | Yes/No | N2: default: No | Yes/No | O2: default: No Preference | P2: default: Standard Presence group | S2: written by the tool

Sheet MGCP Gateways
A1: Action | B1: Domain Name * | C1: Description | D1: Product * | E1: CallManager Group * | F1: Module in Slot 0 | G1: Subunits | H1: Status | I1: Message | J1: Updated
A2: Add / Update / Add/Update / Delete / Skip | B2: Router hostname(.domain), e.g. HQ-ISR | D2: e.g. Cisco ISR 4331 | default: Cisco ISR 4321 | E2: default: Default | F2: e.g. ISR-2NIM-MBRD / ISR-3NIM-MBRD | default: ISR-2NIM-MBRD | G2: subunit:module ; separated, e.g. 1:NIM-1MFT-T1E1-E1 | H2: written by the tool

Sheet Route Groups
A1: Action | B1: Name * | C1: Distribution Algorithm | D1: Devices (in order) * | E1: Status | F1: Message | G1: Updated
A2: Add / Update / Add/Update / Delete / Skip | B2: e.g. RG_PSTN_HQ | C2: default: Top Down | D2: Trunk / gateway endpoint names ; separated | E2: written by the tool

Sheet Route Lists
A1: Action | B1: Name * | C1: Description | D1: CallManager Group * | E1: Enabled | F1: Run On All Active Nodes | G1: Route Groups (in order) * | H1: Status | I1: Message | J1: Updated
A2: Add / Update / Add/Update / Delete / Skip | B2: e.g. RL_PSTN_HQ | D2: default: Default | E2: default: Yes | Yes/No | F2: Yes/No | G2: ; separated. 'Standard Local Route Group' allowed | H2: written by the tool

Sheet Route Patterns
A1: Action | B1: Pattern * | C1: Partition | D1: Description | E1: Route List | F1: Gateway/Trunk | G1: Block Pattern | H1: Urgent Priority | I1: Use External Phone Mask | J1: Calling Party Mask | K1: Calling Party Prefix | L1: Discard Digits | M1: Called Party Mask | N1: Prefix Digits | O1: Network Location | P1: Provide Outside Dial Tone | Q1: Status | R1: Message | S1: Updated
A2: Add / Update / Add/Update / Delete / Skip | B2: e.g. 9.[2-9]XXXXXXX | E2: Use this OR Gateway/Trunk | G2: default: No | Yes/No | H2: Yes/No | I2: default: Default | L2: e.g. PreDot | O2: default: OffNet | P2: Yes/No | Q2: written by the tool

Sheet Translation Patterns
A1: Action | B1: Pattern * | C1: Partition | D1: Description | E1: CSS | F1: Use Originator's CSS | G1: Block Pattern | H1: Urgent Priority | I1: Use External Phone Mask | J1: Calling Party Mask | K1: Calling Party Prefix | L1: Discard Digits | M1: Called Party Mask | N1: Prefix Digits | O1: Provide Outside Dial Tone | P1: Status | Q1: Message | R1: Updated
A2: Add / Update / Add/Update / Delete / Skip | F2: Yes/No | G2: default: No | Yes/No | H2: default: Yes | Yes/No | I2: default: Default | O2: default: No | Yes/No | P2: written by the tool

Sheet Calling Party Xforms
A1: Action | B1: Pattern * | C1: Partition | D1: Description | E1: Calling Party Mask | F1: Prefix Digits | G1: Discard Digits | H1: Use External Phone Mask | I1: Calling Line ID Presentation | J1: Status | K1: Message | L1: Updated
A2: Add / Update / Add/Update / Delete / Skip | H2: default: Default | J2: written by the tool

Sheet Called Party Xforms
A1: Action | B1: Pattern * | C1: Partition | D1: Description | E1: Called Party Mask | F1: Prefix Digits | G1: Discard Digits | H1: Status | I1: Message | J1: Updated
A2: Add / Update / Add/Update / Delete / Skip | H2: written by the tool

Sheet Voicemail Pilots
A1: Action | B1: Pilot Number * | C1: CSS | D1: Description | E1: Default | F1: Status | G1: Message | H1: Updated
A2: Add / Update / Add/Update / Delete / Skip | B2: Unity Connection pilot DN | E2: default: No | Yes/No | F2: written by the tool

Sheet Voicemail Profiles
A1: Action | B1: Name * | C1: Description | D1: Pilot Number * | E1: Pilot CSS | F1: Mailbox Mask | G1: Default | H1: Status | I1: Message | J1: Updated
A2: Add / Update / Add/Update / Delete / Skip | B2: e.g. VMP_CUC | G2: default: No | Yes/No | H2: written by the tool

Sheet Call Pickup Groups
A1: Action | B1: Name * | C1: Pickup Number * | D1: Partition | E1: Description | F1: Notification | G1: Notification Timer | H1: Status | I1: Message | J1: Updated
A2: Add / Update / Add/Update / Delete / Skip | B2: e.g. CPG_Sales | F2: default: No Alert | H2: written by the tool

Sheet Conference Now
A1: Action | B1: Number * | C1: Partition | D1: Description | E1: Max Wait For Host (min) | F1: Status | G1: Message | H1: Updated
A2: Add / Update / Add/Update / Delete / Skip | E2: default: 15 | F2: written by the tool

Sheet Universal Line Templates
A1: Action | B1: Name * | C1: Line Description | D1: Partition | E1: Line CSS | F1: Voicemail Profile | G1: Alerting Name | H1: Presence Group | I1: Call Pickup Group | J1: Forward All CSS | K1: Forward Busy/No Answer Destination | L1: Forward Busy/No Answer CSS | M1: No Answer Ring Duration | N1: Status | O1: Message | P1: Updated
A2: Add / Update / Add/Update / Delete / Skip | B2: e.g. ULT_HQ | C2: default: #FirstName# #LastName# | G2: default: #FirstName# #LastName# | H2: default: Standard Presence group | K2: e.g. voicemail pilot | N2: written by the tool

Sheet Universal Device Templates
A1: Action | B1: Name * | C1: Device Description | D1: Device Pool * | E1: Security Profile * | F1: SIP Profile * | G1: Phone Button Template * | H1: Device CSS | I1: Common Phone Profile | J1: Softkey Template | K1: Location | L1: Media Resource List | M1: Presence Group | N1: Line Label | O1: Line Display | P1: External Phone Mask | Q1: Status | R1: Message | S1: Updated
A2: Add / Update / Add/Update / Delete / Skip | B2: e.g. UDT_HQ | C2: default: #FN# #LN# #PRODUCTMODEL# | D2: default: Default | E2: default: Universal Device Template - Model-independent Security Profile | F2: default: Standard SIP Profile | G2: default: Universal Device Template Button Layout | I2: default: Standard Common Phone Profile | J2: default: Standard User | K2: default: Hub_None | M2: default: Standard Presence group | N2: default: #FN# #LN# #EXT# | O2: default: #FN# #LN# | P2: e.g. 2412XXXX | Q2: written by the tool

Sheet Directory Numbers
A1: Action | B1: Directory Number * | C1: Partition | D1: Description | E1: Alerting Name | F1: ASCII Alerting Name | G1: Line CSS | H1: Voicemail Profile | I1: Forward CSS | J1: Forward Busy to VM | K1: Forward No Answer to VM | L1: Forward Unregistered to VM | M1: No Answer Ring Duration | N1: Call Pickup Group | O1: Presence Group | P1: Auto Answer | Q1: Status | R1: Message | S1: Updated
A2: Add / Update / Add/Update / Delete / Skip | B2: e.g. 1001 | I2: CSS for all call-forward types | J2: Yes/No | K2: Yes/No | L2: Yes/No | Q2: written by the tool

Sheet End Users
A1: Action | B1: User ID * | C1: First Name | D1: Last Name * | E1: Display Name | F1: Email | G1: Department | H1: Telephone Number | I1: Password | J1: PIN | K1: Access Control Groups | L1: Home Cluster | M1: IM and Presence | N1: Service Profile | O1: Enable Mobility | P1: Presence Group | Q1: Controlled Devices | R1: Primary Extension | S1: Status | T1: Message | U1: Updated
A2: Add / Update / Add/Update / Delete / Skip | I2: local users only | K2: e.g. Standard CCM End Users;Standard CTI Enabled | L2: default: Yes | Yes/No | M2: Yes/No | O2: Yes/No | P2: default: Standard Presence group | Q2: applied after Phones | R2: 1001/PT_Internal - after Phones | S2: written by the tool

Sheet Phones
A1: Action | B1: Device Name * | C1: Description | D1: Product * | E1: Protocol | F1: Device Pool * | G1: Device CSS | H1: Location | I1: Media Resource List | J1: Phone Button Template * | K1: Softkey Template | L1: Common Phone Profile | M1: Security Profile | N1: SIP Profile | O1: Owner User ID | P1: Lines | Q1: Line 1 Display | R1: Line 1 Label | S1: Line 1 External Mask | T1: Speed Dials | U1: Built In Bridge | V1: Extension Mobility | W1: Status | X1: Message | Y1: Updated
A2: Add / Update / Add/Update / Delete / Skip | B2: SEPxxxxxxxxxxxx / CSFuser / BOTuser | D2: e.g. Cisco 8845 / Cisco Unified Client Services Framework | E2: default: SIP | H2: default: Hub_None | J2: e.g. Standard 8845 SIP | L2: default: Standard Common Phone Profile | M2: e.g. Cisco 8845 - Standard SIP Non-Secure Profile | N2: default: Standard SIP Profile | P2: DN/Partition ; separated, e.g. 1001/PT_Internal | T2: number:label ; separated | V2: Yes/No | W2: written by the tool

Sheet Line Groups
A1: Action | B1: Name * | C1: Distribution Algorithm | D1: RNA Reversion Timeout | E1: No Answer | F1: Busy | G1: Not Available | H1: Members (in order) | I1: Auto Logout On No Answer | J1: Status | K1: Message | L1: Updated
A2: Add / Update / Add/Update / Delete / Skip | B2: e.g. LG_Reception | C2: default: Top Down | D2: default: 10 | E2: default: Try next member; then, try next group in Hunt List | F2: default: Try next member; then, try next group in Hunt List | G2: default: Try next member; then, try next group in Hunt List | H2: DN/Partition ; separated | I2: Yes/No | J2: written by the tool

Sheet Hunt Lists
A1: Action | B1: Name * | C1: Description | D1: CallManager Group * | E1: Enabled | F1: For Voice Mail Usage | G1: Line Groups (in order) * | H1: Status | I1: Message | J1: Updated
A2: Add / Update / Add/Update / Delete / Skip | B2: e.g. HL_Reception | D2: default: Default | E2: default: Yes | Yes/No | F2: Yes/No | H2: written by the tool

Sheet Hunt Pilots
A1: Action | B1: Pattern * | C1: Partition | D1: Description | E1: Hunt List * | F1: Alerting Name | G1: Block Pattern | H1: Provide Outside Dial Tone | I1: Calling Party Mask | J1: Max Hunt Timer (s) | K1: Forward No Answer To | L1: Forward No Answer CSS | M1: Forward Busy To | N1: Forward Busy CSS | O1: Status | P1: Message | Q1: Updated
A2: Add / Update / Add/Update / Delete / Skip | G2: default: No | Yes/No | H2: default: No | Yes/No | O2: written by the tool
